Exception ignored in: <module 'threading' from '/usr/lib/python3.8/threading.py'>
Traceback (most recent call last):
  File "/usr/lib/python3.8/threading.py", line 1388, in _shutdown
    lock.acquire()
KeyboardInterrupt: 
Exception ignored in: <module 'threading' from '/usr/lib/python3.8/threading.py'>
Traceback (most recent call last):
  File "/usr/lib/python3.8/threading.py", line 1388, in _shutdown
    lock.acquire()
KeyboardInterrupt: 
Exception ignored in: <module 'threading' from '/usr/lib/python3.8/threading.py'>
Traceback (most recent call last):
  File "/usr/lib/python3.8/threading.py", line 1388, in _shutdown
    lock.acquire()
KeyboardInterrupt: 
Exception ignored in: <module 'threading' from '/usr/lib/python3.8/threading.py'>
Traceback (most recent call last):
  File "/usr/lib/python3.8/threading.py", line 1388, in _shutdown
    lock.acquire()
KeyboardInterrupt: 
Exception ignored in: <module 'threading' from '/usr/lib/python3.8/threading.py'>
Traceback (most recent call last):
  File "/usr/lib/python3.8/threading.py", line 1388, in _shutdown
    lock.acquire()
KeyboardInterrupt: 
Exception ignored in: <module 'threading' from '/usr/lib/python3.8/threading.py'>
Traceback (most recent call last):
  File "/usr/lib/python3.8/threading.py", line 1388, in _shutdown
    lock.acquire()
KeyboardInterrupt: 
Exception ignored in: <module 'threading' from '/usr/lib/python3.8/threading.py'>
Traceback (most recent call last):
  File "/usr/lib/python3.8/threading.py", line 1388, in _shutdown
    lock.acquire()
KeyboardInterrupt: 
Exception ignored in: <module 'threading' from '/usr/lib/python3.8/threading.py'>
Traceback (most recent call last):
  File "/usr/lib/python3.8/threading.py", line 1388, in _shutdown
    lock.acquire()
KeyboardInterrupt: 
Exception ignored in: <module 'threading' from '/usr/lib/python3.8/threading.py'>
Traceback (most recent call last):
  File "/usr/lib/python3.8/threading.py", line 1388, in _shutdown
    lock.acquire()
KeyboardInterrupt: 
Exception ignored in: <module 'threading' from '/usr/lib/python3.8/threading.py'>
Traceback (most recent call last):
  File "/usr/lib/python3.8/threading.py", line 1388, in _shutdown
    lock.acquire()
KeyboardInterrupt: 
Exception ignored in: <module 'threading' from '/usr/lib/python3.8/threading.py'>
Traceback (most recent call last):
  File "/usr/lib/python3.8/threading.py", line 1388, in _shutdown
    lock.acquire()
KeyboardInterrupt: 
Exception ignored in: <module 'threading' from '/usr/lib/python3.8/threading.py'>
Traceback (most recent call last):
  File "/usr/lib/python3.8/threading.py", line 1388, in _shutdown
    lock.acquire()
KeyboardInterrupt: 
Exception ignored in: <module 'threading' from '/usr/lib/python3.8/threading.py'>
Traceback (most recent call last):
  File "/usr/lib/python3.8/threading.py", line 1388, in _shutdown
    lock.acquire()
KeyboardInterrupt: 
Exception ignored in: <module 'threading' from '/usr/lib/python3.8/threading.py'>
Traceback (most recent call last):
  File "/usr/lib/python3.8/threading.py", line 1388, in _shutdown
    lock.acquire()
KeyboardInterrupt: 
Exception ignored in: <module 'threading' from '/usr/lib/python3.8/threading.py'>
Traceback (most recent call last):
  File "/usr/lib/python3.8/threading.py", line 1388, in _shutdown
    lock.acquire()
KeyboardInterrupt: 
Exception ignored in: <module 'threading' from '/usr/lib/python3.8/threading.py'>
Traceback (most recent call last):
  File "/usr/lib/python3.8/threading.py", line 1388, in _shutdown
    lock.acquire()
KeyboardInterrupt: 
Exception ignored in: Exception ignored in: <module 'threading' from '/usr/lib/python3.8/threading.py'>
Traceback (most recent call last):
  File "/usr/lib/python3.8/threading.py", line 1388, in _shutdown
<module 'threading' from '/usr/lib/python3.8/threading.py'>
Traceback (most recent call last):
  File "/usr/lib/python3.8/threading.py", line 1388, in _shutdown
    lock.acquire()
KeyboardInterrupt: 
    lock.acquire()
KeyboardInterrupt: 
Exception ignored in: <module 'threading' from '/usr/lib/python3.8/threading.py'>
Traceback (most recent call last):
  File "/usr/lib/python3.8/threading.py", line 1388, in _shutdown
    lock.acquire()
KeyboardInterrupt: 
Exception ignored in: <module 'threading' from '/usr/lib/python3.8/threading.py'>
Traceback (most recent call last):
  File "/usr/lib/python3.8/threading.py", line 1388, in _shutdown
    lock.acquire()
KeyboardInterrupt: 
Exception ignored in: <module 'threading' from '/usr/lib/python3.8/threading.py'>
Traceback (most recent call last):
  File "/usr/lib/python3.8/threading.py", line 1388, in _shutdown
    lock.acquire()
KeyboardInterrupt: 
Exception ignored in: <module 'threading' from '/usr/lib/python3.8/threading.py'>
Traceback (most recent call last):
  File "/usr/lib/python3.8/threading.py", line 1388, in _shutdown
    lock.acquire()
KeyboardInterrupt: 
Exception ignored in: <module 'threading' from '/usr/lib/python3.8/threading.py'>
Traceback (most recent call last):
  File "/usr/lib/python3.8/threading.py", line 1388, in _shutdown
Exception ignored in: <module 'threading' from '/usr/lib/python3.8/threading.py'>
Traceback (most recent call last):
  File "/usr/lib/python3.8/threading.py", line 1388, in _shutdown
    lock.acquire()
KeyboardInterrupt: 
    lock.acquire()
KeyboardInterrupt: 
Exception ignored in: <module 'threading' from '/usr/lib/python3.8/threading.py'>
Traceback (most recent call last):
  File "/usr/lib/python3.8/threading.py", line 1388, in _shutdown
    lock.acquire()
KeyboardInterrupt: 
Exception ignored in: <module 'threading' from '/usr/lib/python3.8/threading.py'>
Traceback (most recent call last):
  File "/usr/lib/python3.8/threading.py", line 1388, in _shutdown
    lock.acquire()
KeyboardInterrupt: 
Exception ignored in: <module 'threading' from '/usr/lib/python3.8/threading.py'>
Traceback (most recent call last):
  File "/usr/lib/python3.8/threading.py", line 1388, in _shutdown
    lock.acquire()
KeyboardInterrupt: 
Exception ignored in: <module 'threading' from '/usr/lib/python3.8/threading.py'>
Traceback (most recent call last):
  File "/usr/lib/python3.8/threading.py", line 1388, in _shutdown
    lock.acquire()
KeyboardInterrupt: 
Exception ignored in: <module 'threading' from '/usr/lib/python3.8/threading.py'>
Traceback (most recent call last):
  File "/usr/lib/python3.8/threading.py", line 1388, in _shutdown
    lock.acquire()
KeyboardInterrupt: 
Exception ignored in: <module 'threading' from '/usr/lib/python3.8/threading.py'>
Traceback (most recent call last):
  File "/usr/lib/python3.8/threading.py", line 1388, in _shutdown
    lock.acquire()
KeyboardInterrupt: 
Exception ignored in: <module 'threading' from '/usr/lib/python3.8/threading.py'>
Traceback (most recent call last):
  File "/usr/lib/python3.8/threading.py", line 1388, in _shutdown
    lock.acquire()
KeyboardInterrupt: 
Exception ignored in: <module 'threading' from '/usr/lib/python3.8/threading.py'>
Traceback (most recent call last):
  File "/usr/lib/python3.8/threading.py", line 1388, in _shutdown
    lock.acquire()
KeyboardInterrupt: 
Exception ignored in: <module 'threading' from '/usr/lib/python3.8/threading.py'>
Traceback (most recent call last):
  File "/usr/lib/python3.8/threading.py", line 1388, in _shutdown
    lock.acquire()
KeyboardInterrupt: 
Exception ignored in: <module 'threading' from '/usr/lib/python3.8/threading.py'>
Traceback (most recent call last):
  File "/usr/lib/python3.8/threading.py", line 1388, in _shutdown
    lock.acquire()
KeyboardInterrupt: 
Exception ignored in: <module 'threading' from '/usr/lib/python3.8/threading.py'>
Traceback (most recent call last):
  File "/usr/lib/python3.8/threading.py", line 1388, in _shutdown
    lock.acquire()
KeyboardInterrupt: 
Exception ignored in: <module 'threading' from '/usr/lib/python3.8/threading.py'>
Traceback (most recent call last):
  File "/usr/lib/python3.8/threading.py", line 1388, in _shutdown
    lock.acquire()
KeyboardInterrupt: 
Exception ignored in: <module 'threading' from '/usr/lib/python3.8/threading.py'>
Traceback (most recent call last):
  File "/usr/lib/python3.8/threading.py", line 1388, in _shutdown
Exception ignored in: <module 'threading' from '/usr/lib/python3.8/threading.py'>
Traceback (most recent call last):
  File "/usr/lib/python3.8/threading.py", line 1388, in _shutdown
    lock.acquire()
KeyboardInterrupt: 
    lock.acquire()
KeyboardInterrupt: 
Exception ignored in: <module 'threading' from '/usr/lib/python3.8/threading.py'>
Traceback (most recent call last):
  File "/usr/lib/python3.8/threading.py", line 1388, in _shutdown
    lock.acquire()
KeyboardInterrupt: 
Exception ignored in: <module 'threading' from '/usr/lib/python3.8/threading.py'>
Traceback (most recent call last):
  File "/usr/lib/python3.8/threading.py", line 1388, in _shutdown
    lock.acquire()
KeyboardInterrupt: 
Traceback (most recent call last):
  File "/home/ubuntu/ytbot/bot.py", line 8, in <module>
    import requests
  File "/usr/lib/python3/dist-packages/requests/__init__.py", line 43, in <module>
    import urllib3
  File "/usr/lib/python3/dist-packages/urllib3/__init__.py", line 7, in <module>
    from .connectionpool import HTTPConnectionPool, HTTPSConnectionPool, connection_from_url
  File "/usr/lib/python3/dist-packages/urllib3/connectionpool.py", line 29, in <module>
    from .connection import (
  File "/usr/lib/python3/dist-packages/urllib3/connection.py", line 40, in <module>
    from .util.ssl_ import (
  File "/usr/lib/python3/dist-packages/urllib3/util/__init__.py", line 7, in <module>
    from .ssl_ import (
  File "/usr/lib/python3/dist-packages/urllib3/util/ssl_.py", line 10, in <module>
    from .url import IPV4_RE, BRACELESS_IPV6_ADDRZ_RE
  File "/usr/lib/python3/dist-packages/urllib3/util/url.py", line 61, in <module>
    IPV6_RE = re.compile("^" + IPV6_PAT + "$")
  File "/usr/lib/python3.8/re.py", line 250, in compile
    return _compile(pattern, flags)
  File "/usr/lib/python3.8/re.py", line 302, in _compile
    p = sre_compile.compile(pattern, flags)
  File "/usr/lib/python3.8/sre_compile.py", line 764, in compile
    p = sre_parse.parse(p, flags)
  File "/usr/lib/python3.8/sre_parse.py", line 948, in parse
    p = _parse_sub(source, state, flags & SRE_FLAG_VERBOSE, 0)
  File "/usr/lib/python3.8/sre_parse.py", line 443, in _parse_sub
    itemsappend(_parse(source, state, verbose, nested + 1,
  File "/usr/lib/python3.8/sre_parse.py", line 834, in _parse
    p = _parse_sub(source, state, sub_verbose, nested + 1)
  File "/usr/lib/python3.8/sre_parse.py", line 443, in _parse_sub
    itemsappend(_parse(source, state, verbose, nested + 1,
  File "/usr/lib/python3.8/sre_parse.py", line 511, in _parse
    sourceget()
  File "/usr/lib/python3.8/sre_parse.py", line 256, in get
    self.__next()
  File "/usr/lib/python3.8/sre_parse.py", line 247, in __next
    self.index = index + 1
KeyboardInterrupt
Traceback (most recent call last):
  File "/home/ubuntu/ytbot/bot.py", line 8, in <module>
    import requests
  File "/usr/lib/python3/dist-packages/requests/__init__.py", line 95, in <module>
    from urllib3.contrib import pyopenssl
  File "/usr/lib/python3/dist-packages/urllib3/contrib/pyopenssl.py", line 47, in <module>
    from cryptography import x509
  File "<frozen importlib._bootstrap>", line 1017, in _handle_fromlist
KeyboardInterrupt
Exception ignored in: <module 'threading' from '/usr/lib/python3.8/threading.py'>
Traceback (most recent call last):
  File "/usr/lib/python3.8/threading.py", line 1388, in _shutdown
    lock.acquire()
KeyboardInterrupt: 
Exception ignored in: <module 'threading' from '/usr/lib/python3.8/threading.py'>
Traceback (most recent call last):
  File "/usr/lib/python3.8/threading.py", line 1388, in _shutdown
    lock.acquire()
KeyboardInterrupt: 
Traceback (most recent call last):
  File "/home/ubuntu/ytbot/bot.py", line 8, in <module>
    import requests
  File "/usr/lib/python3/dist-packages/requests/__init__.py", line 43, in <module>
    import urllib3
  File "/usr/lib/python3/dist-packages/urllib3/__init__.py", line 7, in <module>
    from .connectionpool import HTTPConnectionPool, HTTPSConnectionPool, connection_from_url
  File "/usr/lib/python3/dist-packages/urllib3/connectionpool.py", line 38, in <module>
    from .request import RequestMethods
  File "/usr/lib/python3/dist-packages/urllib3/request.py", line 10, in <module>
    class RequestMethods(object):
KeyboardInterrupt
Traceback (most recent call last):
  File "/home/ubuntu/ytbot/bot.py", line 102, in <module>
    proxy1 = proxy()
  File "/home/ubuntu/ytbot/bot.py", line 100, in __init__
    time.sleep(1)
KeyboardInterrupt
Exception ignored in: <module 'threading' from '/usr/lib/python3.8/threading.py'>
Traceback (most recent call last):
  File "/usr/lib/python3.8/threading.py", line 1388, in _shutdown
    lock.acquire()
KeyboardInterrupt: 
Exception ignored in: <module 'threading' from '/usr/lib/python3.8/threading.py'>
Traceback (most recent call last):
  File "/usr/lib/python3.8/threading.py", line 1388, in _shutdown
    lock.acquire()
KeyboardInterrupt: 
Traceback (most recent call last):
  File "/home/ubuntu/ytbot/bot.py", line 132, in <module>
    threading.Thread(target=bot).start()
  File "/usr/lib/python3.8/threading.py", line 857, in start
    self._started.wait()
  File "/usr/lib/python3.8/threading.py", line 558, in wait
    signaled = self._cond.wait(timeout)
  File "/usr/lib/python3.8/threading.py", line 302, in wait
    waiter.acquire()
KeyboardInterrupt
Traceback (most recent call last):
  File "/home/ubuntu/ytbot/bot.py", line 132, in <module>
    threading.Thread(target=bot).start()
  File "/usr/lib/python3.8/threading.py", line 857, in start
    self._started.wait()
  File "/usr/lib/python3.8/threading.py", line 558, in wait
    signaled = self._cond.wait(timeout)
  File "/usr/lib/python3.8/threading.py", line 302, in wait
    waiter.acquire()
KeyboardInterrupt
Traceback (most recent call last):
  File "/home/ubuntu/ytbot/bot.py", line 132, in <module>
    threading.Thread(target=bot).start()
  File "/usr/lib/python3.8/threading.py", line 857, in start
    self._started.wait()
  File "/usr/lib/python3.8/threading.py", line 558, in wait
    signaled = self._cond.wait(timeout)
  File "/usr/lib/python3.8/threading.py", line 302, in wait
    waiter.acquire()
KeyboardInterrupt
Traceback (most recent call last):
  File "/home/ubuntu/ytbot/bot.py", line 132, in <module>
    threading.Thread(target=bot).start()
  File "/usr/lib/python3.8/threading.py", line 857, in start
    self._started.wait()
  File "/usr/lib/python3.8/threading.py", line 558, in wait
    signaled = self._cond.wait(timeout)
  File "/usr/lib/python3.8/threading.py", line 302, in wait
    waiter.acquire()
KeyboardInterrupt
Exception ignored in: <module 'threading' from '/usr/lib/python3.8/threading.py'>
Traceback (most recent call last):
  File "/usr/lib/python3.8/threading.py", line 1388, in _shutdown
    lock.acquire()
KeyboardInterrupt: 
Exception ignored in: <module 'threading' from '/usr/lib/python3.8/threading.py'>
Traceback (most recent call last):
  File "/usr/lib/python3.8/threading.py", line 1388, in _shutdown
    lock.acquire()
KeyboardInterrupt: 
Exception ignored in: <module 'threading' from '/usr/lib/python3.8/threading.py'>
Traceback (most recent call last):
  File "/usr/lib/python3.8/threading.py", line 1388, in _shutdown
    lock.acquire()
KeyboardInterrupt: 
Exception ignored in: <module 'threading' from '/usr/lib/python3.8/threading.py'>
Traceback (most recent call last):
  File "/usr/lib/python3.8/threading.py", line 1388, in _shutdown
    lock.acquire()
KeyboardInterrupt: 
Exception ignored in: <module 'threading' from '/usr/lib/python3.8/threading.py'>
Traceback (most recent call last):
  File "/usr/lib/python3.8/threading.py", line 1388, in _shutdown
    lock.acquire()
KeyboardInterrupt: 
Exception ignored in: <module 'threading' from '/usr/lib/python3.8/threading.py'>
Traceback (most recent call last):
  File "/usr/lib/python3.8/threading.py", line 1388, in _shutdown
    lock.acquire()
KeyboardInterrupt: 
Exception ignored in: <module 'threading' from '/usr/lib/python3.8/threading.py'>
Traceback (most recent call last):
  File "/usr/lib/python3.8/threading.py", line 1388, in _shutdown
    lock.acquire()
KeyboardInterrupt: 
Exception ignored in: <module 'threading' from '/usr/lib/python3.8/threading.py'>
Traceback (most recent call last):
  File "/usr/lib/python3.8/threading.py", line 1388, in _shutdown
    lock.acquire()
KeyboardInterrupt: 
Exception ignored in: <module 'threading' from '/usr/lib/python3.8/threading.py'>
Traceback (most recent call last):
  File "/usr/lib/python3.8/threading.py", line 1388, in _shutdown
    lock.acquire()
KeyboardInterrupt: 
Exception ignored in: <module 'threading' from '/usr/lib/python3.8/threading.py'>
Traceback (most recent call last):
  File "/usr/lib/python3.8/threading.py", line 1388, in _shutdown
    lock.acquire()
KeyboardInterrupt: 
Exception ignored in: <module 'threading' from '/usr/lib/python3.8/threading.py'>
Traceback (most recent call last):
  File "/usr/lib/python3.8/threading.py", line 1388, in _shutdown
    lock.acquire()
KeyboardInterrupt: 
Exception ignored in: <module 'threading' from '/usr/lib/python3.8/threading.py'>
Traceback (most recent call last):
  File "/usr/lib/python3.8/threading.py", line 1388, in _shutdown
    lock.acquire()
KeyboardInterrupt: 
Exception ignored in: <module 'threading' from '/usr/lib/python3.8/threading.py'>
Traceback (most recent call last):
  File "/usr/lib/python3.8/threading.py", line 1388, in _shutdown
    lock.acquire()
KeyboardInterrupt: 
Exception ignored in: <module 'threading' from '/usr/lib/python3.8/threading.py'>
Traceback (most recent call last):
  File "/usr/lib/python3.8/threading.py", line 1388, in _shutdown
    lock.acquire()
KeyboardInterrupt: 
Exception ignored in: <module 'threading' from '/usr/lib/python3.8/threading.py'>
Traceback (most recent call last):
  File "/usr/lib/python3.8/threading.py", line 1388, in _shutdown
    lock.acquire()
KeyboardInterrupt: 
Exception ignored in: <module 'threading' from '/usr/lib/python3.8/threading.py'>
Traceback (most recent call last):
  File "/usr/lib/python3.8/threading.py", line 1388, in _shutdown
    lock.acquire()
KeyboardInterrupt: 
Exception ignored in: <module 'threading' from '/usr/lib/python3.8/threading.py'>
Traceback (most recent call last):
  File "/usr/lib/python3.8/threading.py", line 1388, in _shutdown
    lock.acquire()
KeyboardInterrupt: 
Exception ignored in: <module 'threading' from '/usr/lib/python3.8/threading.py'>
Traceback (most recent call last):
  File "/usr/lib/python3.8/threading.py", line 1388, in _shutdown
    lock.acquire()
KeyboardInterrupt: 
Exception ignored in: <module 'threading' from '/usr/lib/python3.8/threading.py'>
Traceback (most recent call last):
  File "/usr/lib/python3.8/threading.py", line 1388, in _shutdown
    lock.acquire()
KeyboardInterrupt: 
Exception ignored in: <module 'threading' from '/usr/lib/python3.8/threading.py'>
Traceback (most recent call last):
  File "/usr/lib/python3.8/threading.py", line 1388, in _shutdown
    lock.acquire()
KeyboardInterrupt: 
Exception ignored in: <module 'threading' from '/usr/lib/python3.8/threading.py'>
Traceback (most recent call last):
  File "/usr/lib/python3.8/threading.py", line 1388, in _shutdown
    lock.acquire()
KeyboardInterrupt: 
Exception ignored in: <module 'threading' from '/usr/lib/python3.8/threading.py'>
Traceback (most recent call last):
  File "/usr/lib/python3.8/threading.py", line 1388, in _shutdown
    lock.acquire()
KeyboardInterrupt: 
Exception ignored in: <module 'threading' from '/usr/lib/python3.8/threading.py'>
Traceback (most recent call last):
  File "/usr/lib/python3.8/threading.py", line 1388, in _shutdown
    lock.acquire()
KeyboardInterrupt: 
Exception ignored in: <module 'threading' from '/usr/lib/python3.8/threading.py'>
Traceback (most recent call last):
  File "/usr/lib/python3.8/threading.py", line 1388, in _shutdown
    lock.acquire()
KeyboardInterrupt: 
Exception ignored in: <module 'threading' from '/usr/lib/python3.8/threading.py'>
Traceback (most recent call last):
  File "/usr/lib/python3.8/threading.py", line 1388, in _shutdown
    lock.acquire()
KeyboardInterrupt: 
Exception ignored in: <module 'threading' from '/usr/lib/python3.8/threading.py'>
Traceback (most recent call last):
  File "/usr/lib/python3.8/threading.py", line 1388, in _shutdown
    lock.acquire()
KeyboardInterrupt: 
Exception ignored in: <module 'threading' from '/usr/lib/python3.8/threading.py'>
Traceback (most recent call last):
  File "/usr/lib/python3.8/threading.py", line 1388, in _shutdown
    lock.acquire()
KeyboardInterrupt: 
Exception ignored in: <module 'threading' from '/usr/lib/python3.8/threading.py'>
Traceback (most recent call last):
  File "/usr/lib/python3.8/threading.py", line 1388, in _shutdown
    lock.acquire()
KeyboardInterrupt: 
Exception ignored in: <module 'threading' from '/usr/lib/python3.8/threading.py'>
Traceback (most recent call last):
  File "/usr/lib/python3.8/threading.py", line 1388, in _shutdown
    lock.acquire()
KeyboardInterrupt: 
Exception ignored in: <module 'threading' from '/usr/lib/python3.8/threading.py'>
Traceback (most recent call last):
  File "/usr/lib/python3.8/threading.py", line 1388, in _shutdown
    lock.acquire()
KeyboardInterrupt: 
Exception ignored in: <module 'threading' from '/usr/lib/python3.8/threading.py'>
Traceback (most recent call last):
  File "/usr/lib/python3.8/threading.py", line 1388, in _shutdown
    lock.acquire()
KeyboardInterrupt: 
Exception ignored in: <module 'threading' from '/usr/lib/python3.8/threading.py'>
Traceback (most recent call last):
  File "/usr/lib/python3.8/threading.py", line 1388, in _shutdown
    lock.acquire()
KeyboardInterrupt: 
Exception ignored in: <module 'threading' from '/usr/lib/python3.8/threading.py'>
Traceback (most recent call last):
  File "/usr/lib/python3.8/threading.py", line 1388, in _shutdown
Exception ignored in: <module 'threading' from '/usr/lib/python3.8/threading.py'>
Traceback (most recent call last):
  File "/usr/lib/python3.8/threading.py", line 1388, in _shutdown
    lock.acquire()
KeyboardInterrupt: 
    lock.acquire()
KeyboardInterrupt: 
Exception ignored in: <module 'threading' from '/usr/lib/python3.8/threading.py'>
Traceback (most recent call last):
  File "/usr/lib/python3.8/threading.py", line 1388, in _shutdown
    lock.acquire()
KeyboardInterrupt: 
Exception ignored in: <module 'threading' from '/usr/lib/python3.8/threading.py'>
Traceback (most recent call last):
  File "/usr/lib/python3.8/threading.py", line 1388, in _shutdown
    lock.acquire()
KeyboardInterrupt: 
Traceback (most recent call last):
  File "/home/ubuntu/ytbot/bot.py", line 8, in <module>
    import requests
  File "/usr/lib/python3/dist-packages/requests/__init__.py", line 112, in <module>
    from . import utils
  File "/usr/lib/python3/dist-packages/requests/utils.py", line 26, in <module>
    from ._internal_utils import to_native_string
  File "/usr/lib/python3/dist-packages/requests/_internal_utils.py", line 11, in <module>
    from .compat import is_py2, builtin_str, str
  File "/usr/lib/python3/dist-packages/requests/compat.py", line 58, in <module>
    from urllib.request import parse_http_list, getproxies, proxy_bypass, proxy_bypass_environment, getproxies_environment
  File "/usr/lib/python3.8/urllib/request.py", line 941, in <module>
    class AbstractBasicAuthHandler:
  File "/usr/lib/python3.8/urllib/request.py", line 948, in AbstractBasicAuthHandler
    rx = re.compile('(?:^|,)'   # start of the string or ','
  File "/usr/lib/python3.8/re.py", line 250, in compile
    return _compile(pattern, flags)
  File "/usr/lib/python3.8/re.py", line 302, in _compile
    p = sre_compile.compile(pattern, flags)
  File "/usr/lib/python3.8/sre_compile.py", line 764, in compile
    p = sre_parse.parse(p, flags)
  File "/usr/lib/python3.8/sre_parse.py", line 948, in parse
    p = _parse_sub(source, state, flags & SRE_FLAG_VERBOSE, 0)
  File "/usr/lib/python3.8/sre_parse.py", line 443, in _parse_sub
    itemsappend(_parse(source, state, verbose, nested + 1,
  File "/usr/lib/python3.8/sre_parse.py", line 834, in _parse
    p = _parse_sub(source, state, sub_verbose, nested + 1)
  File "/usr/lib/python3.8/sre_parse.py", line 443, in _parse_sub
    itemsappend(_parse(source, state, verbose, nested + 1,
  File "/usr/lib/python3.8/sre_parse.py", line 680, in _parse
    subpattern[-1] = (MAX_REPEAT, (min, max, item))
KeyboardInterrupt
Traceback (most recent call last):
  File "/home/ubuntu/ytbot/bot.py", line 8, in <module>
    import requests
  File "/usr/lib/python3/dist-packages/requests/__init__.py", line 95, in <module>
    from urllib3.contrib import pyopenssl
  File "/usr/lib/python3/dist-packages/urllib3/contrib/pyopenssl.py", line 48, in <module>
    from cryptography.hazmat.backends.openssl import backend as openssl_backend
  File "/usr/lib/python3/dist-packages/cryptography/hazmat/backends/openssl/__init__.py", line 7, in <module>
    from cryptography.hazmat.backends.openssl.backend import backend
  File "/usr/lib/python3/dist-packages/cryptography/hazmat/backends/openssl/backend.py", line 38, in <module>
    from cryptography.hazmat.backends.openssl.ec import (
  File "/usr/lib/python3/dist-packages/cryptography/hazmat/backends/openssl/ec.py", line 139, in <module>
    class _EllipticCurvePrivateKey(object):
  File "/usr/lib/python3/dist-packages/cryptography/utils.py", line 47, in register_decorator
    verify_interface(iface, klass)
  File "/usr/lib/python3/dist-packages/cryptography/utils.py", line 107, in verify_interface
    actual = signature(getattr(klass, method))
  File "/usr/lib/python3.8/inspect.py", line 3093, in signature
    return Signature.from_callable(obj, follow_wrapped=follow_wrapped)
  File "/usr/lib/python3.8/inspect.py", line 2842, in from_callable
    return _signature_from_callable(obj, sigcls=cls,
  File "/usr/lib/python3.8/inspect.py", line 2234, in _signature_from_callable
    obj = unwrap(obj, stop=(lambda f: hasattr(f, "__signature__")))
  File "/usr/lib/python3.8/inspect.py", line 520, in unwrap
    while _is_wrapper(func):
KeyboardInterrupt
Exception ignored in: <module 'threading' from '/usr/lib/python3.8/threading.py'>
Traceback (most recent call last):
  File "/usr/lib/python3.8/threading.py", line 1388, in _shutdown
    lock.acquire()
KeyboardInterrupt: 
Exception ignored in: <module 'threading' from '/usr/lib/python3.8/threading.py'>
Traceback (most recent call last):
  File "/usr/lib/python3.8/threading.py", line 1388, in _shutdown
    lock.acquire()
KeyboardInterrupt: 
Exception ignored in: <module 'threading' from '/usr/lib/python3.8/threading.py'>
Traceback (most recent call last):
  File "/usr/lib/python3.8/threading.py", line 1388, in _shutdown
    lock.acquire()
KeyboardInterrupt: 
Exception ignored in: <module 'threading' from '/usr/lib/python3.8/threading.py'>
Traceback (most recent call last):
  File "/usr/lib/python3.8/threading.py", line 1388, in _shutdown
    lock.acquire()
KeyboardInterrupt: 
Traceback (most recent call last):
  File "/home/ubuntu/ytbot/bot.py", line 132, in <module>
    threading.Thread(target=bot).start()
  File "/usr/lib/python3.8/threading.py", line 857, in start
Traceback (most recent call last):
  File "/home/ubuntu/ytbot/bot.py", line 132, in <module>
    threading.Thread(target=bot).start()
  File "/usr/lib/python3.8/threading.py", line 857, in start
    self._started.wait()
  File "/usr/lib/python3.8/threading.py", line 558, in wait
    signaled = self._cond.wait(timeout)
  File "/usr/lib/python3.8/threading.py", line 302, in wait
    waiter.acquire()
KeyboardInterrupt
Traceback (most recent call last):
  File "/home/ubuntu/ytbot/bot.py", line 132, in <module>
    threading.Thread(target=bot).start()
  File "/usr/lib/python3.8/threading.py", line 857, in start
    self._started.wait()
  File "/usr/lib/python3.8/threading.py", line 558, in wait
    signaled = self._cond.wait(timeout)
  File "/usr/lib/python3.8/threading.py", line 302, in wait
    waiter.acquire()
KeyboardInterrupt
    self._started.wait()
  File "/usr/lib/python3.8/threading.py", line 558, in wait
    signaled = self._cond.wait(timeout)
  File "/usr/lib/python3.8/threading.py", line 302, in wait
    waiter.acquire()
KeyboardInterrupt
Traceback (most recent call last):
  File "/home/ubuntu/ytbot/bot.py", line 132, in <module>
    threading.Thread(target=bot).start()
  File "/usr/lib/python3.8/threading.py", line 857, in start
    self._started.wait()
  File "/usr/lib/python3.8/threading.py", line 558, in wait
    signaled = self._cond.wait(timeout)
  File "/usr/lib/python3.8/threading.py", line 302, in wait
    waiter.acquire()
KeyboardInterrupt
Exception ignored in: <module 'threading' from '/usr/lib/python3.8/threading.py'>
Traceback (most recent call last):
  File "/usr/lib/python3.8/threading.py", line 1388, in _shutdown
    lock.acquire()
KeyboardInterrupt: 
Exception ignored in: <module 'threading' from '/usr/lib/python3.8/threading.py'>
Traceback (most recent call last):
  File "/usr/lib/python3.8/threading.py", line 1388, in _shutdown
    lock.acquire()
KeyboardInterrupt: 
Exception ignored in: <module 'threading' from '/usr/lib/python3.8/threading.py'>
Traceback (most recent call last):
  File "/usr/lib/python3.8/threading.py", line 1388, in _shutdown
    lock.acquire()
KeyboardInterrupt: 
Exception ignored in: <module 'threading' from '/usr/lib/python3.8/threading.py'>
Traceback (most recent call last):
  File "/usr/lib/python3.8/threading.py", line 1388, in _shutdown
    lock.acquire()
KeyboardInterrupt: 
Traceback (most recent call last):
  File "/home/ubuntu/ytbot/bot.py", line 102, in <module>
    proxy1 = proxy()
  File "/home/ubuntu/ytbot/bot.py", line 100, in __init__
    time.sleep(1)
KeyboardInterrupt
Traceback (most recent call last):
  File "/home/ubuntu/ytbot/bot.py", line 102, in <module>
    proxy1 = proxy()
  File "/home/ubuntu/ytbot/bot.py", line 100, in __init__
    time.sleep(1)
KeyboardInterrupt
Exception ignored in: <module 'threading' from '/usr/lib/python3.8/threading.py'>
Traceback (most recent call last):
  File "/usr/lib/python3.8/threading.py", line 1388, in _shutdown
    lock.acquire()
KeyboardInterrupt: 
Exception ignored in: <module 'threading' from '/usr/lib/python3.8/threading.py'>
Traceback (most recent call last):
  File "/usr/lib/python3.8/threading.py", line 1388, in _shutdown
    lock.acquire()
KeyboardInterrupt: 
Exception ignored in: <module 'threading' from '/usr/lib/python3.8/threading.py'>
Traceback (most recent call last):
  File "/usr/lib/python3.8/threading.py", line 1388, in _shutdown
    lock.acquire()
KeyboardInterrupt: 
Exception ignored in: <module 'threading' from '/usr/lib/python3.8/threading.py'>
Traceback (most recent call last):
  File "/usr/lib/python3.8/threading.py", line 1388, in _shutdown
    lock.acquire()
KeyboardInterrupt: 
Traceback (most recent call last):
  File "/home/ubuntu/ytbot/bot.py", line 132, in <module>
    threading.Thread(target=bot).start()
  File "/usr/lib/python3.8/threading.py", line 857, in start
    self._started.wait()
  File "/usr/lib/python3.8/threading.py", line 558, in wait
    signaled = self._cond.wait(timeout)
  File "/usr/lib/python3.8/threading.py", line 302, in wait
    waiter.acquire()
KeyboardInterrupt
Traceback (most recent call last):
  File "/home/ubuntu/ytbot/bot.py", line 132, in <module>
    threading.Thread(target=bot).start()
  File "/usr/lib/python3.8/threading.py", line 857, in start
    self._started.wait()
  File "/usr/lib/python3.8/threading.py", line 558, in wait
    signaled = self._cond.wait(timeout)
  File "/usr/lib/python3.8/threading.py", line 302, in wait
    waiter.acquire()
KeyboardInterrupt
Traceback (most recent call last):
  File "/home/ubuntu/ytbot/bot.py", line 132, in <module>
Traceback (most recent call last):
    threading.Thread(target=bot).start()
  File "/usr/lib/python3.8/threading.py", line 857, in start
    self._started.wait()
  File "/usr/lib/python3.8/threading.py", line 558, in wait
    signaled = self._cond.wait(timeout)
  File "/usr/lib/python3.8/threading.py", line 302, in wait
    waiter.acquire()
KeyboardInterrupt
  File "/home/ubuntu/ytbot/bot.py", line 132, in <module>
    threading.Thread(target=bot).start()
  File "/usr/lib/python3.8/threading.py", line 857, in start
    self._started.wait()
  File "/usr/lib/python3.8/threading.py", line 558, in wait
    signaled = self._cond.wait(timeout)
  File "/usr/lib/python3.8/threading.py", line 302, in wait
    waiter.acquire()
KeyboardInterrupt
Traceback (most recent call last):
  File "/home/ubuntu/ytbot/bot.py", line 132, in <module>
    threading.Thread(target=bot).start()
  File "/usr/lib/python3.8/threading.py", line 857, in start
    self._started.wait()
  File "/usr/lib/python3.8/threading.py", line 558, in wait
    signaled = self._cond.wait(timeout)
  File "/usr/lib/python3.8/threading.py", line 302, in wait
    waiter.acquire()
KeyboardInterrupt
Traceback (most recent call last):
  File "/home/ubuntu/ytbot/bot.py", line 132, in <module>
    threading.Thread(target=bot).start()
  File "/usr/lib/python3.8/threading.py", line 857, in start
    self._started.wait()
  File "/usr/lib/python3.8/threading.py", line 558, in wait
    signaled = self._cond.wait(timeout)
  File "/usr/lib/python3.8/threading.py", line 302, in wait
    waiter.acquire()
KeyboardInterrupt
Traceback (most recent call last):
  File "/home/ubuntu/ytbot/bot.py", line 132, in <module>
    threading.Thread(target=bot).start()
  File "/usr/lib/python3.8/threading.py", line 857, in start
    self._started.wait()
  File "/usr/lib/python3.8/threading.py", line 558, in wait
    signaled = self._cond.wait(timeout)
  File "/usr/lib/python3.8/threading.py", line 302, in wait
    waiter.acquire()
KeyboardInterrupt
Traceback (most recent call last):
  File "/home/ubuntu/ytbot/bot.py", line 132, in <module>
    threading.Thread(target=bot).start()
  File "/usr/lib/python3.8/threading.py", line 857, in start
    self._started.wait()
  File "/usr/lib/python3.8/threading.py", line 558, in wait
    signaled = self._cond.wait(timeout)
  File "/usr/lib/python3.8/threading.py", line 302, in wait
    waiter.acquire()
KeyboardInterrupt
Exception ignored in: <module 'threading' from '/usr/lib/python3.8/threading.py'>
Traceback (most recent call last):
  File "/usr/lib/python3.8/threading.py", line 1388, in _shutdown
    lock.acquire()
KeyboardInterrupt: 
Exception ignored in: <module 'threading' from '/usr/lib/python3.8/threading.py'>
Traceback (most recent call last):
  File "/usr/lib/python3.8/threading.py", line 1388, in _shutdown
    lock.acquire()
KeyboardInterrupt: 
Exception ignored in: <module 'threading' from '/usr/lib/python3.8/threading.py'>
Traceback (most recent call last):
  File "/usr/lib/python3.8/threading.py", line 1388, in _shutdown
    lock.acquire()
KeyboardInterrupt: 
Exception ignored in: <module 'threading' from '/usr/lib/python3.8/threading.py'>
Traceback (most recent call last):
  File "/usr/lib/python3.8/threading.py", line 1388, in _shutdown
    lock.acquire()
KeyboardInterrupt: 
Exception ignored in: <module 'threading' from '/usr/lib/python3.8/threading.py'>
Traceback (most recent call last):
  File "/usr/lib/python3.8/threading.py", line 1388, in _shutdown
    lock.acquire()
KeyboardInterrupt: 
Exception ignored in: <module 'threading' from '/usr/lib/python3.8/threading.py'>
Traceback (most recent call last):
  File "/usr/lib/python3.8/threading.py", line 1388, in _shutdown
    lock.acquire()
KeyboardInterrupt: 
Exception ignored in: <module 'threading' from '/usr/lib/python3.8/threading.py'>
Traceback (most recent call last):
  File "/usr/lib/python3.8/threading.py", line 1388, in _shutdown
    lock.acquire()
KeyboardInterrupt: 
Exception ignored in: <module 'threading' from '/usr/lib/python3.8/threading.py'>
Traceback (most recent call last):
  File "/usr/lib/python3.8/threading.py", line 1388, in _shutdown
    lock.acquire()
KeyboardInterrupt: 
Exception ignored in: <module 'threading' from '/usr/lib/python3.8/threading.py'>
Traceback (most recent call last):
  File "/usr/lib/python3.8/threading.py", line 1388, in _shutdown
    lock.acquire()
KeyboardInterrupt: 
Exception ignored in: <module 'threading' from '/usr/lib/python3.8/threading.py'>
Traceback (most recent call last):
  File "/usr/lib/python3.8/threading.py", line 1388, in _shutdown
    lock.acquire()
KeyboardInterrupt: 
Exception ignored in: <module 'threading' from '/usr/lib/python3.8/threading.py'>
Traceback (most recent call last):
  File "/usr/lib/python3.8/threading.py", line 1388, in _shutdown
Exception ignored in: <module 'threading' from '/usr/lib/python3.8/threading.py'>
Traceback (most recent call last):
  File "/usr/lib/python3.8/threading.py", line 1388, in _shutdown
    lock.acquire()
    lock.acquire()
KeyboardInterrupt: 
KeyboardInterrupt: 
Exception ignored in: <module 'threading' from '/usr/lib/python3.8/threading.py'>
Traceback (most recent call last):
  File "/usr/lib/python3.8/threading.py", line 1388, in _shutdown
    lock.acquire()
KeyboardInterrupt: 
Exception ignored in: <module 'threading' from '/usr/lib/python3.8/threading.py'>
Traceback (most recent call last):
  File "/usr/lib/python3.8/threading.py", line 1388, in _shutdown
    lock.acquire()
KeyboardInterrupt: 
Exception ignored in: <module 'threading' from '/usr/lib/python3.8/threading.py'>
Traceback (most recent call last):
  File "/usr/lib/python3.8/threading.py", line 1388, in _shutdown
    lock.acquire()
KeyboardInterrupt: 
Exception ignored in: <module 'threading' from '/usr/lib/python3.8/threading.py'>
Traceback (most recent call last):
  File "/usr/lib/python3.8/threading.py", line 1388, in _shutdown
    lock.acquire()
KeyboardInterrupt: 
